Workbook
Name ___mo1: #REF!
Name __mo1: #REF!
Name _mo1: #REF!
Name AsOf: #REF!
Name aum_fee: #REF!
Name Bath: #REF!
Name Bed: #REF!
Name bond_AV_rate: #REF!
Name broker_fee: #REF!
Name CU?: #REF!
Name CUpt2: #REF!
Name CurrentEmpOtherConc: #REF!
Name CurrentInPlaceRent: #REF!
Name CurrentIsMonthToMonth: #REF!
Name CurrentLeaseExpirationDate: #REF!
Name CurrentLeaseSignedDate: #REF!
Name CurrentLeaseTerm: #REF!
Name CurrentMoveInDate: #REF!
Name CurrentMoveOutDate: #REF!
Name CurrentNetEffectiveRent: #REF!
Name CurrentOtherIncome: #REF!
Name CurrentRecurringConc: #REF!
Name CurrentSuppRent: #REF!
Name CurrentUpfrontConc: #REF!
Name DealName: #REF!
Name DealUnits: #REF!
Name Equity_Share_GP: #REF!
Name Equity_Share_LP: #REF!
Name FC_IRR: #REF!
Name fee_lot: #REF!
Name FF_1: #REF!
Name FF_2: #REF!
Name FF_3: #REF!
Name FF_4: #REF!
Name fin_rate: #REF!
Name FloorPlan: #REF!
Name FutureEmpOtherConc: #REF!
Name FutureInPlaceRent: #REF!
Name FutureLeaseColumn: #REF!
Name FutureLeaseExpiration: #REF!
Name FutureLeaseSignedDate: #REF!
Name FutureLeaseTerm: #REF!
Name FutureMoveInDate: #REF!
Name FutureNetEffectiveRent: #REF!
Name FutureOtherIncome: #REF!
Name FutureRecurringConc: #REF!
Name FutureSuppRent: #REF!
Name FutureUpfrontConc: #REF!
Name hurd1_IRR: #REF!
Name hurd2_IRR: #REF!
Name inv_share_equity: #REF!
Name inv_share_hurd1: #REF!
Name inv_share_hurd2: #REF!
Name inv_share_hurd3: #REF!
Name IO_Period: #REF!
Name IsEdit: #REF!
Name IsNoticeToVacate: #REF!
Name land_acre: #REF!
Name land_plan_lot: #REF!
Name Lev_IRR: #REF!

Sheet I. LeaseUp Template
B1: Lease-Up / Inventory Report - March 2026
B3: # of Units | C3: 117
B4: =COUNT('Data Table'!P2:P118) -> 57 | E4: =COUNTIF('Data Table'!O2:O118,"Tenant Occupied*") -> 55 | H4: =F14 -> 52 | K4: =F19 -> 53 | N4: =F24 -> 6
B6: Executed Leases To Date | E6: Current Occupancy | H6: Ending Occupancy March Budget | K6: Ending Occupancy March Actual | N6: Net Absorption March 2026
B7: =B4/C3 -> 0.48717949 | E7: =E4/C3 -> 0.47008547 | H7: =H4/C3 -> 0.44444444 | K7: =K4/C3 -> 0.45299145 | N7: =N4/C3 -> 0.051282051
B9: OCCUPANCY BY MONTH
D10: 46023 | E10: 46054 | F10: 46082 | G10: 46113 | H10: 46143 | I10: 46174 | J10: 46204 | K10: 46235 | L10: 46266 | M10: 46296 | N10: 46327 | O10: 46357 | P10: Total / Avg
H11: 2026 Budget
B12: Beginning | D12: 33 | E12: =D14 -> 40 | F12: =E14 -> 47 | G12: =F14 -> 52 | H12: =G14 -> 58 | I12: =H14 -> 68 | J12: =I14 -> 77 | K12: =J14 -> 85 | L12: =K14 -> 91 | ... O12: =N14 -> 104
B13: Absorption (# Units) | D13: =D14-D12 -> 7 | E13: =E14-E12 -> 7 | F13: =F14-F12 -> 5 | G13: =G14-G12 -> 6 | H13: =H14-H12 -> 10 | I13: =I14-I12 -> 9 | J13: =J14-J12 -> 8 | K13: =K14-K12 -> 6 | ... O13: =O14-O12 -> 3
B14: Ending OCC | D14: 40 | E14: 47 | F14: 52 | G14: 58 | H14: 68 | I14: 77 | J14: 85 | K14: 91 | L14: 96 | M14: 100 | N14: 104 | O14: 107 | P14: =O14 -> 107
B15: OCC % | D15: =D14/117 -> 0.34188034 | E15: =E14/117 -> 0.4017094 | F15: =F14/117 -> 0.44444444 | G15: =G14/117 -> 0.4957265 | H15: =H14/117 -> 0.58119658 | I15: =I14/117 -> 0.65811966 | J15: =J14/117 -> 0.72649573 | K15: =K14/117 -> 0.77777778 | ... P15: =P14/117 -> 0.91452991
H17: Actual + Projected
B18: Beginning | D18: 33 | E18: =D19 -> 41 | F18: =E19 -> 47 | G18: =F19 -> 53 | H18: =G19 -> 56 | I18: =H19 -> 57 | J18: =I19 -> 57 | K18: =J19 -> 57 | L18: =K19 -> 57 | ... P18: =O19 -> 57
B19: Ending OCC | D19: 41 | E19: =E18+E24 -> 47 | F19: =F18+F24 -> 53 | G19: =G18+G24 -> 56 | H19: =H18+H24 -> 57 | I19: =I18+I24 -> 57 | J19: =J18+J24 -> 57 | K19: =K18+K24 -> 57 | L19: =L18+L24 -> 57 | ... O19: =O18+O24 -> 57 | P19: =O19 -> 57
B20: OCC % | D20: =D19/$C$3 -> 0.35042735 | E20: =E19/$C$3 -> 0.4017094 | F20: =F19/$C$3 -> 0.45299145 | G20: =G19/$C$3 -> 0.47863248 | H20: =H19/$C$3 -> 0.48717949 | I20: =I19/$C$3 -> 0.48717949 | J20: =J19/$C$3 -> 0.48717949 | K20: =K19/$C$3 -> 0.48717949 | ... P20: =P19/$C$3 -> 0.48717949
B22: Move-ins | D22: =D19-D18 -> 8 | E22: ='Lease Tracker'!M14 -> 7 | F22: ='Lease Tracker'!N14 -> 6 | G22: ='Lease Tracker'!O14 -> 3 | H22: ='Lease Tracker'!P14 -> 1 | I22: ='Lease Tracker'!Q14 -> 1 | J22: ='Lease Tracker'!R14 -> 0 | K22: ='Lease Tracker'!S14 -> 0 | L22: ='Lease Tracker'!T14 -> 0 | ... O22: ='Lease Tracker'!W14 -> 0 | P22: =SUM(D22:O22) -> 26
B23: Move-Outs | E23: ='Lease Tracker'!M15 -> -1 | F23: ='Lease Tracker'!N15 -> 0 | G23: ='Lease Tracker'!O15 -> 0 | H23: ='Lease Tracker'!P15 -> 0 | I23: ='Lease Tracker'!Q15 -> -1 | J23: ='Lease Tracker'!R15 -> 0 | K23: ='Lease Tracker'!S15 -> 0 | L23: ='Lease Tracker'!T15 -> 0 | ... O23: ='Lease Tracker'!W15 -> 0 | P23: =SUM(D23:O23) -> -2
B24: Net Absorption | D24: =D23+D22 -> 8 | E24: =E23+E22 -> 6 | F24: =F23+F22 -> 6 | G24: =G23+G22 -> 3 | H24: =H23+H22 -> 1 | I24: =I23+I22 -> 0 | J24: =J23+J22 -> 0 | K24: =K23+K22 -> 0 | ... O24: =O23+O22 -> 0
B26: # Units Leased, Actual | D26: ='Lease Tracker'!L13 -> 8 | E26: 5 | F26: ='Lease Tracker'!N13 -> 3 | G26: ='Lease Tracker'!O13 -> 3 | H26: ='Lease Tracker'!P13 -> 0 | I26: ='Lease Tracker'!Q13 -> 0 | J26: ='Lease Tracker'!R13 -> 0 | K26: ='Lease Tracker'!S13 -> 0 | L26: ='Lease Tracker'!T13 -> 0 | M26: ='Lease Tracker'!U13 -> 0 | ... O26: ='Lease Tracker'!W13 -> 0 | P26: =SUM(D26:O26) -> 19
B27: Lease Expirations | E27: 0
B28: Renewals | F28: 2
B29: Cumulative Leases | D29: 47 | E29: =D29+E26+E27 -> 52 | F29: =E29+F26+F27 -> 55 | G29: =F29+G26+G27 -> 58 | H29: =G29+H26+H27 -> 58 | I29: =H29+I26+I27 -> 58 | J29: =I29+J26+J27 -> 58 | K29: =J29+K26+K27 -> 58 | L29: =K29+L26+L27 -> 58 | ... O29: =N29+O26+O27 -> 58 | P29: =O29 -> 58
D30: =D29/$C$3 -> 0.4017094 | E30: =E29/$C$3 -> 0.44444444 | F30: =F29/$C$3 -> 0.47008547 | G30: =G29/$C$3 -> 0.4957265 | H30: =H29/$C$3 -> 0.4957265 | I30: =I29/$C$3 -> 0.4957265 | J30: =J29/$C$3 -> 0.4957265 | K30: =K29/$C$3 -> 0.4957265 | ... O30: =O29/$C$3 -> 0.4957265
B31: Internal Proforma Budget
B32: # of Occ Units | D32: 44 | E32: 52 | F32: 60 | G32: 68 | H32: 76 | I32: 84 | J32: 92 | K32: 100 | L32: 108 | M32: 116 | N32: 116 | O32: 116 | P32: 116
B33: Ending OCC % | D33: =D32/117 -> 0.37606838 | E33: =E32/117 -> 0.44444444 | F33: =F32/117 -> 0.51282051 | G33: =G32/117 -> 0.58119658 | H33: =H32/117 -> 0.64957265 | I33: =I32/117 -> 0.71794872 | J33: =J32/117 -> 0.78632479 | K33: =K32/117 -> 0.85470085 | ... P33: =P32/117 -> 0.99145299
B35: LEASING PACE
B48: TRAFFIC SUMMARY & CONVERSIONS
G49: Total Traffic | H49: Prospects | I49: Tours | J49: Applications | K49: Cancels | L49: Denials | M49: Net Leases
D50: Mar 2026 | G50: 179 | H50: 83 | I50: 30 | J50: 6 | K50: 2 | L50: 1 | M50: =J50-K50-L50 -> 3
D51: Feb 2026 | G51: 187 | H51: 108 | I51: 26 | J51: ='Weekly Traffic'!E18 -> 0 | K51: ='Weekly Traffic'!G18 -> 0 | L51: ='Weekly Traffic'!H18 -> 0 | M51: =J51-K51-L51 -> 0
F52: Current Month Conversion: | H52: =IFERROR(H50/G50,0) -> 0.46368715 | I52: =IFERROR(I50/H50,0) -> 0.36144578 | J52: =IFERROR(J50/I50,0) -> 0.2 | M52: =IFERROR(M50/J50,0) -> 0.5
F53: KPIs | H53: Lead>Prosp. | I53: Prosp.>Tours | J53: Tour >App. | K53: App.>Leases
H54: 60% + | I54: 25% + | J54: 35% + | K54: 60%+
B55: Comments:
B56: Traffic was down in the month of February; however the team's conversions exceeded KPIs.
B59: LEASING BY PHASE
D60: 1 | E60: 2 | F60: 3 | G60: 4 | H60: 5 | I60: 6 | J60: Total | K60: % | L60: Comments:
B61: Floorplan | D61: Complete | E61: T/O Date | F61: T/O Date | G61: 45961 | H61: 45991 | I61: 46022 | J61: Units / Plan | K61: Leased | L61: Our leasing strategy is focused on incentivizing residents to move in by mid-month for the month to drive revenues up & meet / exceed leasing goals for the month. For April, we are short on our goals for ending occupancy and have adjusted specials to encourage lease-up through April to meet budget.
...

Sheet II. Operational Template
B1: Operational Performance Report -March 2026
B7: 2026 BUDGET
C8: 46023 | D8: 46054 | E8: 46082 | F8: 46113 | G8: 46143 | H8: 46174 | I8: 46204 | J8: 46235 | K8: 46266 | L8: 46296 | M8: 46327 | N8: 46357 | O8: Total
C9: Budget | D9: Budget | E9: Budget | F9: Budget | G9: Budget | H9: Budget | I9: Budget | J9: Budget | K9: Budget | L9: Budget | M9: Budget | N9: Budget | O9: Budget
B11: NET RENTAL INCOME | C11: 89547 | D11: 109020 | E11: 122894 | F11: 138055 | G11: 154866 | H11: 181029 | I11: 203852 | J11: 220987 | K11: 233397 | L11: 256543 | M11: 274671 | N11: 283349 | O11: 2268210 | Q11: 2268210
B12: UTILITY INCOME | C12: 2535 | D12: 3052 | E12: 3446 | F12: 3949 | G12: 4662 | H12: 5465 | I12: 6129 | J12: 6530 | K12: 6924 | L12: 7305 | M12: 7752 | N12: 7920 | O12: =SUM(C12:N12) -> 65669 | Q12: 70922
B13: OTHER INCOME | C13: 7497 | D13: 8277 | E13: 9493 | F13: 10453 | G13: 12978 | H13: 13483 | I13: 14699 | J13: 15304 | K13: 14179 | L13: 13852 | M13: 15043 | N13: 15109 | O13: =SUM(C13:N13) -> 150367 | Q13: 150367
B14: TOTAL INCOME | C14: =SUM(C11:C13) -> 99579 | D14: =SUM(D11:D13) -> 120349 | E14: =SUM(E11:E13) -> 135833 | F14: =SUM(F11:F13) -> 152457 | G14: =SUM(G11:G13) -> 172506 | H14: =SUM(H11:H13) -> 199977 | I14: =SUM(I11:I13) -> 224680 | J14: =SUM(J11:J13) -> 242821 | ... O14: =SUM(O11:O13) -> 2484246
B15: OPERATING EXPENSES | C15: -59578 | D15: -57242 | E15: -60885 | F15: -65666 | G15: -57912 | H15: -71094 | I15: -72040 | J15: -59844 | K15: -59452 | L15: -60779 | M15: -48389 | N15: -51827 | O15: =SUM(C15:N15) -> -724708 | Q15: -721994
B16: FIXED EXPENSES | C16: -7500 | D16: -7500 | E16: -7500 | F16: -7500 | G16: -7500 | H16: -7500 | I16: -83930 | J16: -83930 | K16: -83930 | L16: -83930 | M16: -83930 | N16: -83930 | O16: =SUM(C16:N16) -> -548580 | Q16: -1007160
B17: NOI | C17: =C14+C15+C16 -> 32501 | D17: =D14+D15+D16 -> 55607 | E17: =E14+E15+E16 -> 67448 | F17: =F14+F15+F16 -> 79291 | G17: =G14+G15+G16 -> 107094 | H17: =H14+H15+H16 -> 121383 | I17: =I14+I15+I16 -> 68710 | J17: =J14+J15+J16 -> 99047 | ... O17: =O14+O15+O16 -> 1210958 | Q17: 760345
B19: CAPITAL IMPVMTS | C19: 0 | D19: 0 | E19: -1200 | F19: 0 | G19: 0 | H19: -7700 | I19: 0 | J19: 0 | K19: -1200 | L19: 0 | M19: 0 | N19: -1200 | O19: =SUM(C19:N19) -> -11300
B21: NOI / CASH FLOW | C21: =C17+C19 -> 32501 | D21: =D17+D19 -> 55607 | E21: =E17+E19 -> 66248 | F21: =F17+F19 -> 79291 | G21: =G17+G19 -> 107094 | H21: =H17+H19 -> 113683 | I21: =I17+I19 -> 68710 | J21: =J17+J19 -> 99047 | ... O21: =O17+O19 -> 1199658
B23: 2026 FORECAST
C24: 46023 | D24: 46054 | E24: 46082 | F24: 46113 | G24: 46143 | H24: 46174 | I24: 46204 | J24: 46235 | K24: 46266 | L24: 46296 | M24: 46327 | N24: 46357 | O24: Total
C25: Actual | D25: Actual | E25: Actual | F25: Budget | G25: Budget | H25: Budget | I25: Budget | J25: Budget | K25: Budget | L25: Budget | M25: Budget | N25: Budget | O25: Budget
B27: NET RENTAL INCOME | C27: 80971.03 | D27: 72170.14 | E27: 112999.88 | F27: 138055 | G27: 154866 | H27: 181029 | I27: 203852 | J27: 220987 | K27: 233397 | L27: 256543 | M27: 274671 | N27: 283349 | O27: =SUM(C27:N27) -> 2212890
B28: UTILITY INCOME | C28: 2705.74 | D28: 2806.38 | E28: 3592.85 | F28: 3949 | G28: 4662 | H28: 5465 | I28: 6129 | J28: 6530 | K28: 6924 | L28: 7305 | M28: 7752 | N28: 7920 | O28: =SUM(C28:N28) -> 65740.97
B29: OTHER INCOME | C29: 9037.36 | D29: 6086.37 | E29: 8200.39 | F29: 10453 | G29: 12978 | H29: 13483 | I29: 14699 | J29: 15304 | K29: 14179 | L29: 13852 | M29: 15043 | N29: 15109 | O29: =SUM(C29:N29) -> 148424.12
B30: TOTAL INCOME | C30: =SUM(C27:C29) -> 92714.13 | D30: =SUM(D27:D29) -> 81062.89 | E30: =SUM(E27:E29) -> 124793.12 | F30: =SUM(F27:F29) -> 152457 | G30: =SUM(G27:G29) -> 172506 | H30: =SUM(H27:H29) -> 199977 | I30: =SUM(I27:I29) -> 224680 | J30: =SUM(J27:J29) -> 242821 | ... N30: =SUM(N27:N29) -> 306378 | O30: =SUM(C30:N30) -> 2427055.1
B31: OPERATING EXPENSES | C31: -60895.72 | D31: =-73990.88+7500 -> -66490.88 | E31: =-55480.17+7500 -> -47980.17 | F31: -65666 | G31: -57912 | H31: -71094 | I31: -72040 | J31: -59844 | K31: -59452 | L31: -60779 | M31: -48389 | N31: -51827 | O31: =SUM(C31:N31) -> -722369.77
B32: FIXED EXPENSES | C32: =-7500 -> -7500 | D32: -7500 | E32: -7500 | F32: -7500 | G32: -7500 | H32: -7500 | I32: -83930 | J32: -83930 | K32: -83930 | L32: -83930 | M32: -83930 | N32: -83930 | O32: =SUM(C32:N32) -> -548580
B33: NOI | C33: =C30+C31+C32 -> 24318.41 | D33: =D30+D31+D32 -> 7072.01 | E33: =E30+E31+E32 -> 69312.95 | F33: =F30+F31+F32 -> 79291 | G33: =G30+G31+G32 -> 107094 | H33: =H30+H31+H32 -> 121383 | I33: =I30+I31+I32 -> 68710 | J33: =J30+J31+J32 -> 99047 | ... O33: =O30+O31+O32 -> 1156105.4
B35: CAPITAL IMPVMTS/PY EXP | C35: -2245 | D35: =-477.74-1894.38 -> -2372.12 | E35: =-3721.38-8660-2000 -> -14381.38 | F35: 0 | G35: 0 | H35: -7700 | I35: 0 | J35: 0 | K35: -1200 | L35: 0 | M35: 0 | N35: -1200 | O35: =SUM(C35:N35) -> -29098.5
B37: FORECASTED NOI / CASH FLOW | C37: =C33+C35 -> 22073.41 | D37: =D33+D35 -> 4699.89 | E37: =E33+E35 -> 54931.57 | F37: =F33+F35 -> 79291 | G37: =G33+G35 -> 107094 | H37: =H33+H35 -> 113683 | I37: =I33+I35 -> 68710 | J37: =J33+J35 -> 99047 | ... O37: =O33+O35 -> 1127006.9
B38: Variance Forcast to Budget | C38: =C37-C21 -> -10427.59 | D38: =D37-D21 -> -50907.11 | E38: =E37-E21 -> -11316.43 | F38: =F37-F21 -> 0 | G38: =G37-G21 -> 0 | H38: =H37-H21 -> 0 | I38: =I37-I21 -> 0 | J38: =J37-J21 -> 0 | ... O38: =O37-O21 -> -72651.13
B39: D2/ LENDER PROFORMA
B40: NET RENTAL INCOME | C40: 96017.212 | D40: 108835.5 | E40: 123078.05 | F40: 137320.6 | G40: 153476.7 | H40: 176886.1 | I40: 204678.29 | J40: 229680.65 | K40: 250461.59 | L40: 266999.11 | M40: 280746.79 | N40: 293070.22 | O40: =SUM(C40:N40) -> 2321250.8
B41: TOTAL OTHER INCOME, INCL. UTILITY | C41: 7034.2746 | D41: 7871.6882 | E41: 8709.1019 | F41: 9713.9982 | G41: 11418.152 | H41: 12962.585 | I41: 14346.005 | J41: 15397.91 | K41: 16285.351 | L41: 17007.034 | M41: 17732.167 | N41: 18289.817 | O41: =SUM(C41:N41) -> 156768.08 | P41: =O41+O40 -> 2478018.9
B42: OPERATING EXPENSES | C42: -60694 | D42: -62104 | E42: -60692 | F42: -64973 | G42: -63188 | H42: -70856 | I42: -71302 | J42: -65703 | K42: -59750 | L42: -60077 | M42: -53765 | N42: -51625 | O42: =SUM(C42:N42) -> -744729
B43: FIXED EXPENSES | C43: -7500 | D43: -7500 | E43: -7500 | F43: -7500 | G43: -7500 | H43: -7500 | I43: -83930 | J43: -83930 | K43: -83930 | L43: -83930 | M43: -83930 | N43: -86416 | O43: =SUM(C43:N43) -> -551066
B44: TOTAL PROJECTED CASH FLOW - D2 | C44: =SUM(C40:C43) -> 34857.486 | D44: =SUM(D40:D43) -> 47103.193 | E44: =SUM(E40:E43) -> 63595.155 | F44: =SUM(F40:F43) -> 74561.599 | G44: =SUM(G40:G43) -> 94206.852 | H44: =SUM(H40:H43) -> 111492.69 | I44: =SUM(I40:I43) -> 63792.297 | J44: =SUM(J40:J43) -> 95445.561 | ... N44: =SUM(N40:N43) -> 173319.04 | O44: =SUM(C44:N44) -> 1182223.9
B45: Variance Budget to Proforma | C45: =C37-C44 -> -12784.076 | D45: =D37-D44 -> -42403.303 | E45: =E37-E44 -> -8663.5847 | F45: =F37-F44 -> 4729.4008 | G45: =G37-G44 -> 12887.148 | H45: =H37-H44 -> 2190.3126 | I45: =I37-I44 -> 4917.7029 | J45: =J37-J44 -> 3601.4387 | ... O45: =O37-O44 -> -55217.036
B47: BUDGET TO ACTUAL & CASH FLOW
C48: 46082 | D48: 46082 | E48: Act v Bud
C49: Actual | D49: Budget | E49: Variance | F49: Comments
B50: NET RENTAL INCOME | C50: 112999.88 | D50: =E11 -> 122894 | E50: =C50-D50 -> -9894.12 | F50: Actual monthly weighted average occupancy was lower than budget, due to half of the move-ins occuring on the last 3 days of the month
B51: UTILITY INCOME | C51: 3592.85 | D51: =E12 -> 3446 | E51: =C51-D51 -> 146.85 | R51: $85 app fee per applicant | U51: Concessions hit the books 30 days following a resident's move-in.
B52: OTHER INCOME | C52: 8200.39 | D52: =E13 -> 9493 | E52: =C52-D52 -> -1292.61 | F52: Came in lower on application & lease admin fees, but double on pet fees. | R52: $200 admin fee | U52: E.G. if a resident moves in on Jan 30, they pay 2 days of rent in Jan, all of Feb and then March gets hit with the full concession
B53: OPERATING EXPENSES | C53: -47980.17 | D53: =E15 -> -60885 | E53: =C53-D53 -> 12904.83 | F53: Under budget in payroll due to no svc mgr; mar | R53: $99 App / Admin Fee for L&L
...

Sheet Data Table
A1: Block | B1: Lot | C1: House # | D1: Rent Roll | E1: Match | F1: Address | G1: Tenant | H1: Inventory | I1: House Type | J1: Floorplan | K1: Bedrooms | L1: SQFT | M1: Phase | N1: Turnover Date | O1: Status | P1: Lease Executed Date | Q1: Tenant Move-In Date | R1: Tenant Move Out Date | S1: Average Rent | T1: $/SQFT | W1: No Match | X1: =COUNTIF(E2:E118,W1) -> 61
A2: 1 | B2: 38 | C2: 47 | D2: =IF(ISNUMBER(SEARCH("Bobby Meadow",F2)),LEFT(F2,FIND(" ",F2)-1)&"M",IF(ISNUMBER(SEARCH("Bruce Rushing",F2)),LEFT(F2,FIND(" ",F2)-1)&"R",LEFT(F2,FIND(" ",F2)-1)&MID(F2,FIND(" ",F2)+1,1))) -> 21901R | E2: =IFERROR(IF(_xlfn.XMATCH(D2,'Rent Roll - RPM'!$B$3:$B$60,0,1)>0,"Match","No Match"),"No Match") -> No Match | F2: 21901 Bruce Rushing Lane | G2: =_xlfn.XLOOKUP(D2,'Rent Roll - RPM'!$B$3:$B$60,'Rent Roll - RPM'!$D$3:$D$60,0) -> 0 | H2: 1 | I2: F3 | J2: Raven | K2: 3 Bed | L2: 1852 | M2: 3 | N2: Complete | O2: Turned | P2: =_xlfn.XLOOKUP(D2,'Rent Roll - RPM'!$B$3:$B$60,'Rent Roll - RPM'!$Q$3:$Q$60,"") | Q2: =_xlfn.XLOOKUP($D2,'Rent Roll - RPM'!$B$3:$B$60,'Rent Roll - RPM'!$R$3:$R$60,"") | R2: =_xlfn.XLOOKUP(D2,'Rent Roll - RPM'!$B$3:$B$60,'Rent Roll - RPM'!$S$3:$S$60,"") | S2: 2950 | T2: =S2/L2 -> 1.5928726 | W2: Match | X2: =COUNTIF(E2:E119,W2) -> 56 | Y2: Leased
A3: 1 | B3: 39 | C3: 46 | D3: =IF(ISNUMBER(SEARCH("Bobby Meadow",F3)),LEFT(F3,FIND(" ",F3)-1)&"M",IF(ISNUMBER(SEARCH("Bruce Rushing",F3)),LEFT(F3,FIND(" ",F3)-1)&"R",LEFT(F3,FIND(" ",F3)-1)&MID(F3,FIND(" ",F3)+1,1))) -> 21905R | E3: =IFERROR(IF(_xlfn.XMATCH(D3,'Rent Roll - RPM'!$B$3:$B$60,0,1)>0,"Match","No Match"),"No Match") -> No Match | F3: 21905 Bruce Rushing Lane | G3: =_xlfn.XLOOKUP(D3,'Rent Roll - RPM'!$B$3:$B$60,'Rent Roll - RPM'!$D$3:$D$60,0) -> 0 | H3: 1 | I3: F2 | J3: Raven | K3: 3 Bed | L3: 1852 | M3: 3 | N3: Complete | O3: Turned | P3: =_xlfn.XLOOKUP(D3,'Rent Roll - RPM'!$B$3:$B$60,'Rent Roll - RPM'!$Q$3:$Q$60,"") | Q3: =_xlfn.XLOOKUP($D3,'Rent Roll - RPM'!$B$3:$B$60,'Rent Roll - RPM'!$R$3:$R$60,"") | R3: =_xlfn.XLOOKUP(D3,'Rent Roll - RPM'!$B$3:$B$60,'Rent Roll - RPM'!$S$3:$S$60,"") | S3: 2950 | T3: =S3/L3 -> 1.5928726 | Y3: Under Construction
A4: 1 | B4: 25 | C4: 80 | D4: =IF(ISNUMBER(SEARCH("Bobby Meadow",F4)),LEFT(F4,FIND(" ",F4)-1)&"M",LEFT(F4,FIND(" ",F4)-1)&MID(F4,FIND(" ",F4)+1,1)) -> 21907M | E4: =IFERROR(IF(_xlfn.XMATCH(D4,'Rent Roll - RPM'!$B$3:$B$60,0,1)>0,"Match","No Match"),"No Match") -> No Match | F4: 21907 Bobby Meadow Lane | G4: =_xlfn.XLOOKUP(D4,'Rent Roll - RPM'!$B$3:$B$60,'Rent Roll - RPM'!$D$3:$D$60,0) -> 0 | H4: 1 | I4: D1 | J4: Phoenix | K4: 4 Bed | L4: 2431 | M4: 5 | N4: 45991 | O4: Turned | P4: =_xlfn.XLOOKUP(D4,'Rent Roll - RPM'!$B$3:$B$60,'Rent Roll - RPM'!$Q$3:$Q$60,"") | Q4: =_xlfn.XLOOKUP($D4,'Rent Roll - RPM'!$B$3:$B$60,'Rent Roll - RPM'!$R$3:$R$60,"") | R4: =_xlfn.XLOOKUP(D4,'Rent Roll - RPM'!$B$3:$B$60,'Rent Roll - RPM'!$S$3:$S$60,"") | S4: 3600 | T4: =S4/L4 -> 1.4808721 | Y4: Turned
A5: 1 | B5: 40 | C5: 45 | D5: =IF(ISNUMBER(SEARCH("Bobby Meadow",F5)),LEFT(F5,FIND(" ",F5)-1)&"M",IF(ISNUMBER(SEARCH("Bruce Rushing",F5)),LEFT(F5,FIND(" ",F5)-1)&"R",LEFT(F5,FIND(" ",F5)-1)&MID(F5,FIND(" ",F5)+1,1))) -> 21909R | E5: =IFERROR(IF(_xlfn.XMATCH(D5,'Rent Roll - RPM'!$B$3:$B$60,0,1)>0,"Match","No Match"),"No Match") -> No Match | F5: 21909 Bruce Rushing Lane | G5: =_xlfn.XLOOKUP(D5,'Rent Roll - RPM'!$B$3:$B$60,'Rent Roll - RPM'!$D$3:$D$60,0) -> 0 | H5: 1 | I5: A1 | J5: Canary | K5: 2 Bed | L5: 1425 | M5: 3 | N5: Complete | O5: Turned | P5: =_xlfn.XLOOKUP(D5,'Rent Roll - RPM'!$B$3:$B$60,'Rent Roll - RPM'!$Q$3:$Q$60,"") | Q5: =_xlfn.XLOOKUP($D5,'Rent Roll - RPM'!$B$3:$B$60,'Rent Roll - RPM'!$R$3:$R$60,"") | R5: =_xlfn.XLOOKUP(D5,'Rent Roll - RPM'!$B$3:$B$60,'Rent Roll - RPM'!$S$3:$S$60,"") | S5: 2450 | T5: =S5/L5 -> 1.7192982 | Y5: Tenant Occupied
A6: 1 | B6: 41 | C6: 44 | D6: =IF(ISNUMBER(SEARCH("Bobby Meadow",F6)),LEFT(F6,FIND(" ",F6)-1)&"M",IF(ISNUMBER(SEARCH("Bruce Rushing",F6)),LEFT(F6,FIND(" ",F6)-1)&"R",LEFT(F6,FIND(" ",F6)-1)&MID(F6,FIND(" ",F6)+1,1))) -> 21913R | E6: =IFERROR(IF(_xlfn.XMATCH(D6,'Rent Roll - RPM'!$B$3:$B$60,0,1)>0,"Match","No Match"),"No Match") -> No Match | F6: 21913 Bruce Rushing Lane | G6: =_xlfn.XLOOKUP(D6,'Rent Roll - RPM'!$B$3:$B$60,'Rent Roll - RPM'!$D$3:$D$60,0) -> 0 | H6: 1 | I6: A3 | J6: Canary | K6: 2 Bed | L6: 1425 | M6: 3 | N6: Complete | O6: Turned | P6: =_xlfn.XLOOKUP(D6,'Rent Roll - RPM'!$B$3:$B$60,'Rent Roll - RPM'!$Q$3:$Q$60,"") | Q6: =_xlfn.XLOOKUP($D6,'Rent Roll - RPM'!$B$3:$B$60,'Rent Roll - RPM'!$R$3:$R$60,"") | R6: =_xlfn.XLOOKUP(D6,'Rent Roll - RPM'!$B$3:$B$60,'Rent Roll - RPM'!$S$3:$S$60,"") | S6: 2450 | T6: =S6/L6 -> 1.7192982 | Y6: Renewal
A7: 1 | B7: 27 | C7: 78 | D7: =IF(ISNUMBER(SEARCH("Bobby Meadow",F7)),LEFT(F7,FIND(" ",F7)-1)&"M",LEFT(F7,FIND(" ",F7)-1)&MID(F7,FIND(" ",F7)+1,1)) -> 21919M | E7: =IFERROR(IF(_xlfn.XMATCH(D7,'Rent Roll - RPM'!$B$3:$B$60,0,1)>0,"Match","No Match"),"No Match") -> No Match | F7: 21919 Bobby Meadow Lane | G7: =_xlfn.XLOOKUP(D7,'Rent Roll - RPM'!$B$3:$B$60,'Rent Roll - RPM'!$D$3:$D$60,0) -> 0 | H7: 1 | I7: A2 | J7: Canary | K7: 2 Bed | L7: 1425 | M7: 5 | N7: 45991 | O7: Turned | P7: =_xlfn.XLOOKUP(D7,'Rent Roll - RPM'!$B$3:$B$60,'Rent Roll - RPM'!$Q$3:$Q$60,"") | Q7: =_xlfn.XLOOKUP($D7,'Rent Roll - RPM'!$B$3:$B$60,'Rent Roll - RPM'!$R$3:$R$60,"") | R7: =_xlfn.XLOOKUP(D7,'Rent Roll - RPM'!$B$3:$B$60,'Rent Roll - RPM'!$S$3:$S$60,"") | S7: 2450 | T7: =S7/L7 -> 1.7192982
A8: 1 | B8: 43 | C8: 42 | D8: =IF(ISNUMBER(SEARCH("Bobby Meadow",F8)),LEFT(F8,FIND(" ",F8)-1)&"M",IF(ISNUMBER(SEARCH("Bruce Rushing",F8)),LEFT(F8,FIND(" ",F8)-1)&"R",LEFT(F8,FIND(" ",F8)-1)&MID(F8,FIND(" ",F8)+1,1))) -> 21921R | E8: =IFERROR(IF(_xlfn.XMATCH(D8,'Rent Roll - RPM'!$B$3:$B$60,0,1)>0,"Match","No Match"),"No Match") -> No Match | F8: 21921 Bruce Rushing Lane | G8: =_xlfn.XLOOKUP(D8,'Rent Roll - RPM'!$B$3:$B$60,'Rent Roll - RPM'!$D$3:$D$60,0) -> 0 | H8: 1 | I8: F2 | J8: Raven | K8: 3 Bed | L8: 1852 | M8: 3 | N8: Complete | O8: Turned | P8: =_xlfn.XLOOKUP(D8,'Rent Roll - RPM'!$B$3:$B$60,'Rent Roll - RPM'!$Q$3:$Q$60,"") | Q8: =_xlfn.XLOOKUP($D8,'Rent Roll - RPM'!$B$3:$B$60,'Rent Roll - RPM'!$R$3:$R$60,"") | R8: =_xlfn.XLOOKUP(D8,'Rent Roll - RPM'!$B$3:$B$60,'Rent Roll - RPM'!$S$3:$S$60,"") | S8: 2950 | T8: =S8/L8 -> 1.5928726
A9: 1 | B9: 29 | C9: 56 | D9: =IF(ISNUMBER(SEARCH("Bobby Meadow",F9)),LEFT(F9,FIND(" ",F9)-1)&"M",LEFT(F9,FIND(" ",F9)-1)&MID(F9,FIND(" ",F9)+1,1)) -> 21927M | E9: =IFERROR(IF(_xlfn.XMATCH(D9,'Rent Roll - RPM'!$B$3:$B$60,0,1)>0,"Match","No Match"),"No Match") -> No Match | F9: 21927 Bobby Meadow Lane | G9: =_xlfn.XLOOKUP(D9,'Rent Roll - RPM'!$B$3:$B$60,'Rent Roll - RPM'!$D$3:$D$60,0) -> 0 | H9: 1 | I9: B3 | J9: Mallard | K9: 3 Bed | L9: 1685 | M9: 3 | N9: Complete | O9: Turned | P9: =_xlfn.XLOOKUP(D9,'Rent Roll - RPM'!$B$3:$B$60,'Rent Roll - RPM'!$Q$3:$Q$60,"") | Q9: =_xlfn.XLOOKUP($D9,'Rent Roll - RPM'!$B$3:$B$60,'Rent Roll - RPM'!$R$3:$R$60,"") | R9: =_xlfn.XLOOKUP(D9,'Rent Roll - RPM'!$B$3:$B$60,'Rent Roll - RPM'!$S$3:$S$60,"") | S9: 2750 | T9: =S9/L9 -> 1.6320475
A10: 1 | B10: 30 | C10: 55 | D10: =IF(ISNUMBER(SEARCH("Bobby Meadow",F10)),LEFT(F10,FIND(" ",F10)-1)&"M",LEFT(F10,FIND(" ",F10)-1)&MID(F10,FIND(" ",F10)+1,1)) -> 21931M | E10: =IFERROR(IF(_xlfn.XMATCH(D10,'Rent Roll - RPM'!$B$3:$B$60,0,1)>0,"Match","No Match"),"No Match") -> No Match | F10: 21931 Bobby Meadow Lane | G10: =_xlfn.XLOOKUP(D10,'Rent Roll - RPM'!$B$3:$B$60,'Rent Roll - RPM'!$D$3:$D$60,0) -> 0 | H10: 1 | I10: B2 | J10: Raven | K10: 3 Bed | L10: 1852 | M10: 3 | N10: Complete | O10: Turned | P10: =_xlfn.XLOOKUP(D10,'Rent Roll - RPM'!$B$3:$B$60,'Rent Roll - RPM'!$Q$3:$Q$60,"") | Q10: =_xlfn.XLOOKUP($D10,'Rent Roll - RPM'!$B$3:$B$60,'Rent Roll - RPM'!$R$3:$R$60,"") | R10: =_xlfn.XLOOKUP(D10,'Rent Roll - RPM'!$B$3:$B$60,'Rent Roll - RPM'!$S$3:$S$60,"") | S10: 2950 | T10: =S10/L10 -> 1.5928726
A11: 1 | B11: 36 | C11: 49 | D11: =IF(ISNUMBER(SEARCH("Bobby Meadow",F11)),LEFT(F11,FIND(" ",F11)-1)&"M",LEFT(F11,FIND(" ",F11)-1)&MID(F11,FIND(" ",F11)+1,1)) -> 21942M | E11: =IFERROR(IF(_xlfn.XMATCH(D11,'Rent Roll - RPM'!$B$3:$B$60,0,1)>0,"Match","No Match"),"No Match") -> No Match | F11: 21942 Bobby Meadow Lane | G11: =_xlfn.XLOOKUP(D11,'Rent Roll - RPM'!$B$3:$B$60,'Rent Roll - RPM'!$D$3:$D$60,0) -> 0 | H11: 1 | I11: A3 | J11: Canary | K11: 2 Bed | L11: 1425 | M11: 3 | N11: Complete | O11: Turned | P11: =_xlfn.XLOOKUP(D11,'Rent Roll - RPM'!$B$3:$B$60,'Rent Roll - RPM'!$Q$3:$Q$60,"") | Q11: =_xlfn.XLOOKUP($D11,'Rent Roll - RPM'!$B$3:$B$60,'Rent Roll - RPM'!$R$3:$R$60,"") | R11: =_xlfn.XLOOKUP(D11,'Rent Roll - RPM'!$B$3:$B$60,'Rent Roll - RPM'!$S$3:$S$60,"") | S11: 2450 | T11: =S11/L11 -> 1.7192982
A12: 1 | B12: 44 | C12: 31 | D12: =IF(ISNUMBER(SEARCH("Bobby Meadow",F12)),LEFT(F12,FIND(" ",F12)-1)&"M",LEFT(F12,FIND(" ",F12)-1)&MID(F12,FIND(" ",F12)+1,1)) -> 22001L | E12: =IFERROR(IF(_xlfn.XMATCH(D12,'Rent Roll - RPM'!$B$3:$B$60,0,1)>0,"Match","No Match"),"No Match") -> No Match | F12: 22001 Lesley Grove Lane | G12: =_xlfn.XLOOKUP(D12,'Rent Roll - RPM'!$B$3:$B$60,'Rent Roll - RPM'!$D$3:$D$60,0) -> 0 | H12: 1 | I12: D1 | J12: Phoenix | K12: 4 Bed | L12: 2431 | M12: 2 | N12: Complete | O12: Turned | P12: =_xlfn.XLOOKUP(D12,'Rent Roll - RPM'!$B$3:$B$60,'Rent Roll - RPM'!$Q$3:$Q$60,"") | Q12: =_xlfn.XLOOKUP($D12,'Rent Roll - RPM'!$B$3:$B$60,'Rent Roll - RPM'!$R$3:$R$60,"") | R12: =_xlfn.XLOOKUP(D12,'Rent Roll - RPM'!$B$3:$B$60,'Rent Roll - RPM'!$S$3:$S$60,"") | S12: 3600 | T12: =S12/L12 -> 1.4808721
A13: 1 | B13: 66 | C13: 2 | D13: =IF(ISNUMBER(SEARCH("Bobby Meadow",F13)),LEFT(F13,FIND(" ",F13)-1)&"M",LEFT(F13,FIND(" ",F13)-1)&MID(F13,FIND(" ",F13)+1,1)) -> 22006F | E13: =IFERROR(IF(_xlfn.XMATCH(D13,'Rent Roll - RPM'!$B$3:$B$60,0,1)>0,"Match","No Match"),"No Match") -> No Match | F13: 22006 Ferguson Meadow Lane | G13: =_xlfn.XLOOKUP(D13,'Rent Roll - RPM'!$B$3:$B$60,'Rent Roll - RPM'!$D$3:$D$60,0) -> 0 | I13: E3 | J13: Sparrow | K13: 2 Bed | L13: 1635 | M13: 1 | N13: Complete | O13: Turned | P13: =_xlfn.XLOOKUP(D13,'Rent Roll - RPM'!$B$3:$B$60,'Rent Roll - RPM'!$Q$3:$Q$60,"") | Q13: =_xlfn.XLOOKUP($D13,'Rent Roll - RPM'!$B$3:$B$60,'Rent Roll - RPM'!$R$3:$R$60,"") | R13: =_xlfn.XLOOKUP(D13,'Rent Roll - RPM'!$B$3:$B$60,'Rent Roll - RPM'!$S$3:$S$60,"") | S13: 2650 | T13: =S13/L13 -> 1.6207951
A14: 1 | B14: 46 | C14: 29 | D14: =IF(ISNUMBER(SEARCH("Bobby Meadow",F14)),LEFT(F14,FIND(" ",F14)-1)&"M",LEFT(F14,FIND(" ",F14)-1)&MID(F14,FIND(" ",F14)+1,1)) -> 22009L | E14: =IFERROR(IF(_xlfn.XMATCH(D14,'Rent Roll - RPM'!$B$3:$B$60,0,1)>0,"Match","No Match"),"No Match") -> No Match | F14: 22009 Lesley Grove Lane | G14: =_xlfn.XLOOKUP(D14,'Rent Roll - RPM'!$B$3:$B$60,'Rent Roll - RPM'!$D$3:$D$60,0) -> 0 | H14: 1 | I14: C2 | J14: Falcon | K14: 3 Bed | L14: 1909 | M14: 2 | N14: Complete | O14: Turned | P14: =_xlfn.XLOOKUP(D14,'Rent Roll - RPM'!$B$3:$B$60,'Rent Roll - RPM'!$Q$3:$Q$60,"") | Q14: =_xlfn.XLOOKUP($D14,'Rent Roll - RPM'!$B$3:$B$60,'Rent Roll - RPM'!$R$3:$R$60,"") | R14: =_xlfn.XLOOKUP(D14,'Rent Roll - RPM'!$B$3:$B$60,'Rent Roll - RPM'!$S$3:$S$60,"") | S14: 3150 | T14: =S14/L14 -> 1.6500786
A15: 1 | B15: 65 | C15: 3 | D15: =IF(ISNUMBER(SEARCH("Bobby Meadow",F15)),LEFT(F15,FIND(" ",F15)-1)&"M",LEFT(F15,FIND(" ",F15)-1)&MID(F15,FIND(" ",F15)+1,1)) -> 22010F | E15: =IFERROR(IF(_xlfn.XMATCH(D15,'Rent Roll - RPM'!$B$3:$B$60,0,1)>0,"Match","No Match"),"No Match") -> No Match | F15: 22010 Ferguson Meadow Lane | G15: =_xlfn.XLOOKUP(D15,'Rent Roll - RPM'!$B$3:$B$60,'Rent Roll - RPM'!$D$3:$D$60,0) -> 0 | H15: 1 | I15: B3 | J15: Mallard | K15: 3 Bed | L15: 1685 | M15: 1 | N15: Complete | O15: Turned | P15: =_xlfn.XLOOKUP(D15,'Rent Roll - RPM'!$B$3:$B$60,'Rent Roll - RPM'!$Q$3:$Q$60,"") | Q15: =_xlfn.XLOOKUP($D15,'Rent Roll - RPM'!$B$3:$B$60,'Rent Roll - RPM'!$R$3:$R$60,"") | R15: =_xlfn.XLOOKUP(D15,'Rent Roll - RPM'!$B$3:$B$60,'Rent Roll - RPM'!$S$3:$S$60,"") | S15: 2750 | T15: =S15/L15 -> 1.6320475
A16: 3 | B16: 11 | C16: 35 | D16: =IF(ISNUMBER(SEARCH("Bobby Meadow",F16)),LEFT(F16,FIND(" ",F16)-1)&"M",LEFT(F16,FIND(" ",F16)-1)&MID(F16,FIND(" ",F16)+1,1)) -> 22014L | E16: =IFERROR(IF(_xlfn.XMATCH(D16,'Rent Roll - RPM'!$B$3:$B$60,0,1)>0,"Match","No Match"),"No Match") -> No Match | F16: 22014 Lesley Grove Lane | G16: =_xlfn.XLOOKUP(D16,'Rent Roll - RPM'!$B$3:$B$60,'Rent Roll - RPM'!$D$3:$D$60,0) -> 0 | H16: 1 | I16: D2 | J16: Phoenix | K16: 4 Bed | L16: 2431 | M16: 2 | N16: Complete | O16: Turned | P16: =_xlfn.XLOOKUP(D16,'Rent Roll - RPM'!$B$3:$B$60,'Rent Roll - RPM'!$Q$3:$Q$60,"") | Q16: =_xlfn.XLOOKUP($D16,'Rent Roll - RPM'!$B$3:$B$60,'Rent Roll - RPM'!$R$3:$R$60,"") | R16: =_xlfn.XLOOKUP(D16,'Rent Roll - RPM'!$B$3:$B$60,'Rent Roll - RPM'!$S$3:$S$60,"") | S16: 3600 | T16: =S16/L16 -> 1.4808721
A17: 1 | B17: 48 | C17: 27 | D17: =IF(ISNUMBER(SEARCH("Bobby Meadow",F17)),LEFT(F17,FIND(" ",F17)-1)&"M",LEFT(F17,FIND(" ",F17)-1)&MID(F17,FIND(" ",F17)+1,1)) -> 22017L | E17: =IFERROR(IF(_xlfn.XMATCH(D17,'Rent Roll - RPM'!$B$3:$B$60,0,1)>0,"Match","No Match"),"No Match") -> No Match | F17: 22017 Lesley Grove Lane | G17: =_xlfn.XLOOKUP(D17,'Rent Roll - RPM'!$B$3:$B$60,'Rent Roll - RPM'!$D$3:$D$60,0) -> 0 | H17: 1 | I17: F3 | J17: Raven | K17: 3 Bed | L17: 1852 | M17: 2 | N17: Complete | O17: Turned | P17: =_xlfn.XLOOKUP(D17,'Rent Roll - RPM'!$B$3:$B$60,'Rent Roll - RPM'!$Q$3:$Q$60,"") | Q17: =_xlfn.XLOOKUP($D17,'Rent Roll - RPM'!$B$3:$B$60,'Rent Roll - RPM'!$R$3:$R$60,"") | R17: =_xlfn.XLOOKUP(D17,'Rent Roll - RPM'!$B$3:$B$60,'Rent Roll - RPM'!$S$3:$S$60,"") | S17: 2950 | T17: =S17/L17 -> 1.5928726
A18: 3 | B18: 10 | C18: 34 | D18: =IF(ISNUMBER(SEARCH("Bobby Meadow",F18)),LEFT(F18,FIND(" ",F18)-1)&"M",LEFT(F18,FIND(" ",F18)-1)&MID(F18,FIND(" ",F18)+1,1)) -> 22018L | E18: =IFERROR(IF(_xlfn.XMATCH(D18,'Rent Roll - RPM'!$B$3:$B$60,0,1)>0,"Match","No Match"),"No Match") -> No Match | F18: 22018 Lesley Grove Lane | G18: =_xlfn.XLOOKUP(D18,'Rent Roll - RPM'!$B$3:$B$60,'Rent Roll - RPM'!$D$3:$D$60,0) -> 0 | H18: 1 | I18: C1 | J18: Falcon | K18: 3 Bed | L18: 1909 | M18: 2 | N18: Complete | O18: Turned | P18: =_xlfn.XLOOKUP(D18,'Rent Roll - RPM'!$B$3:$B$60,'Rent Roll - RPM'!$Q$3:$Q$60,"") | Q18: =_xlfn.XLOOKUP($D18,'Rent Roll - RPM'!$B$3:$B$60,'Rent Roll - RPM'!$R$3:$R$60,"") | R18: =_xlfn.XLOOKUP(D18,'Rent Roll - RPM'!$B$3:$B$60,'Rent Roll - RPM'!$S$3:$S$60,"") | S18: 3150 | T18: =S18/L18 -> 1.6500786
A19: 1 | B19: 49 | C19: 26 | D19: =IF(ISNUMBER(SEARCH("Bobby Meadow",F19)),LEFT(F19,FIND(" ",F19)-1)&"M",LEFT(F19,FIND(" ",F19)-1)&MID(F19,FIND(" ",F19)+1,1)) -> 22021L | E19: =IFERROR(IF(_xlfn.XMATCH(D19,'Rent Roll - RPM'!$B$3:$B$60,0,1)>0,"Match","No Match"),"No Match") -> No Match | F19: 22021 Lesley Grove Lane | G19: =_xlfn.XLOOKUP(D19,'Rent Roll - RPM'!$B$3:$B$60,'Rent Roll - RPM'!$D$3:$D$60,0) -> 0 | H19: 1 | I19: C3 | J19: Falcon | K19: 3 Bed | L19: 1909 | M19: 2 | N19: Complete | O19: Turned | P19: =_xlfn.XLOOKUP(D19,'Rent Roll - RPM'!$B$3:$B$60,'Rent Roll - RPM'!$Q$3:$Q$60,"") | Q19: =_xlfn.XLOOKUP($D19,'Rent Roll - RPM'!$B$3:$B$60,'Rent Roll - RPM'!$R$3:$R$60,"") | R19: =_xlfn.XLOOKUP(D19,'Rent Roll - RPM'!$B$3:$B$60,'Rent Roll - RPM'!$S$3:$S$60,"") | S19: 3150 | T19: =S19/L19 -> 1.6500786
A20: 1 | B20: 62 | C20: 6 | D20: =IF(ISNUMBER(SEARCH("Bobby Meadow",F20)),LEFT(F20,FIND(" ",F20)-1)&"M",LEFT(F20,FIND(" ",F20)-1)&MID(F20,FIND(" ",F20)+1,1)) -> 22022F | E20: =IFERROR(IF(_xlfn.XMATCH(D20,'Rent Roll - RPM'!$B$3:$B$60,0,1)>0,"Match","No Match"),"No Match") -> No Match | F20: 22022 Ferguson Meadow Lane | G20: =_xlfn.XLOOKUP(D20,'Rent Roll - RPM'!$B$3:$B$60,'Rent Roll - RPM'!$D$3:$D$60,0) -> 0 | H20: 1 | I20: F3 | J20: Raven | K20: 3 Bed | L20: 1852 | M20: 1 | N20: Complete | O20: Turned | P20: =_xlfn.XLOOKUP(D20,'Rent Roll - RPM'!$B$3:$B$60,'Rent Roll - RPM'!$Q$3:$Q$60,"") | Q20: =_xlfn.XLOOKUP($D20,'Rent Roll - RPM'!$B$3:$B$60,'Rent Roll - RPM'!$R$3:$R$60,"") | R20: =_xlfn.XLOOKUP(D20,'Rent Roll - RPM'!$B$3:$B$60,'Rent Roll - RPM'!$S$3:$S$60,"") | S20: 2950 | T20: =S20/L20 -> 1.5928726
A21: 3 | B21: 9 | C21: 33 | D21: =IF(ISNUMBER(SEARCH("Bobby Meadow",F21)),LEFT(F21,FIND(" ",F21)-1)&"M",LEFT(F21,FIND(" ",F21)-1)&MID(F21,FIND(" ",F21)+1,1)) -> 22022L | E21: =IFERROR(IF(_xlfn.XMATCH(D21,'Rent Roll - RPM'!$B$3:$B$60,0,1)>0,"Match","No Match"),"No Match") -> No Match | F21: 22022 Lesley Grove Lane | G21: =_xlfn.XLOOKUP(D21,'Rent Roll - RPM'!$B$3:$B$60,'Rent Roll - RPM'!$D$3:$D$60,0) -> 0 | H21: 1 | I21: F2 | J21: Raven | K21: 3 Bed | L21: 1852 | M21: 2 | N21: Complete | O21: Turned | P21: =_xlfn.XLOOKUP(D21,'Rent Roll - RPM'!$B$3:$B$60,'Rent Roll - RPM'!$Q$3:$Q$60,"") | Q21: =_xlfn.XLOOKUP($D21,'Rent Roll - RPM'!$B$3:$B$60,'Rent Roll - RPM'!$R$3:$R$60,"") | R21: =_xlfn.XLOOKUP(D21,'Rent Roll - RPM'!$B$3:$B$60,'Rent Roll - RPM'!$S$3:$S$60,"") | S21: 2950 | T21: =S21/L21 -> 1.5928726
A22: 2 | B22: 1 | C22: 68 | D22: =IF(ISNUMBER(SEARCH("Bobby Meadow",F22)),LEFT(F22,FIND(" ",F22)-1)&"M",LEFT(F22,FIND(" ",F22)-1)&MID(F22,FIND(" ",F22)+1,1)) -> 7303L | E22: =IFERROR(IF(_xlfn.XMATCH(D22,'Rent Roll - RPM'!$B$3:$B$60,0,1)>0,"Match","No Match"),"No Match") -> No Match | F22: 7303 Leighton Meadow Lane | G22: =_xlfn.XLOOKUP(D22,'Rent Roll - RPM'!$B$3:$B$60,'Rent Roll - RPM'!$D$3:$D$60,0) -> 0 | H22: 1 | I22: F1 | J22: Raven | K22: 3 Bed | L22: 1852 | M22: 4 | N22: 45961 | O22: Leased | P22: 46127 | Q22: =_xlfn.XLOOKUP($D22,'Rent Roll - RPM'!$B$3:$B$60,'Rent Roll - RPM'!$R$3:$R$60,"") | R22: =_xlfn.XLOOKUP(D22,'Rent Roll - RPM'!$B$3:$B$60,'Rent Roll - RPM'!$S$3:$S$60,"") | S22: 2950 | T22: =S22/L22 -> 1.5928726
A23: 1 | B23: 6 | C23: 106 | D23: =IF(ISNUMBER(SEARCH("Bobby Meadow",F23)),LEFT(F23,FIND(" ",F23)-1)&"M",LEFT(F23,FIND(" ",F23)-1)&MID(F23,FIND(" ",F23)+1,1)) -> 7307H | E23: =IFERROR(IF(_xlfn.XMATCH(D23,'Rent Roll - RPM'!$B$3:$B$60,0,1)>0,"Match","No Match"),"No Match") -> No Match | F23: 7307 Hadley Meadow Lane | G23: =_xlfn.XLOOKUP(D23,'Rent Roll - RPM'!$B$3:$B$60,'Rent Roll - RPM'!$D$3:$D$60,0) -> 0 | H23: 1 | I23: C3 | J23: Falcon | K23: 3 Bed | L23: 1909 | M23: 6 | N23: 46006 | O23: Turned | P23: =_xlfn.XLOOKUP(D23,'Rent Roll - RPM'!$B$3:$B$60,'Rent Roll - RPM'!$Q$3:$Q$60,"") | Q23: =_xlfn.XLOOKUP($D23,'Rent Roll - RPM'!$B$3:$B$60,'Rent Roll - RPM'!$R$3:$R$60,"") | R23: =_xlfn.XLOOKUP(D23,'Rent Roll - RPM'!$B$3:$B$60,'Rent Roll - RPM'!$S$3:$S$60,"") | S23: 3150 | T23: =S23/L23 -> 1.6500786
A24: 3 | B24: 15 | C24: 39 | D24: =IF(ISNUMBER(SEARCH("Bobby Meadow",F24)),LEFT(F24,FIND(" ",F24)-1)&"M",LEFT(F24,FIND(" ",F24)-1)&MID(F24,FIND(" ",F24)+1,1)) -> 7310C | E24: =IFERROR(IF(_xlfn.XMATCH(D24,'Rent Roll - RPM'!$B$3:$B$60,0,1)>0,"Match","No Match"),"No Match") -> No Match | F24: 7310 Corey Rushing Lane | G24: =_xlfn.XLOOKUP(D24,'Rent Roll - RPM'!$B$3:$B$60,'Rent Roll - RPM'!$D$3:$D$60,0) -> 0 | H24: 1 | I24: E2 | J24: Sparrow | K24: 2 Bed | L24: 1635 | M24: 2 | N24: Complete | O24: Turned | P24: =_xlfn.XLOOKUP(D24,'Rent Roll - RPM'!$B$3:$B$60,'Rent Roll - RPM'!$Q$3:$Q$60,"") | Q24: =_xlfn.XLOOKUP($D24,'Rent Roll - RPM'!$B$3:$B$60,'Rent Roll - RPM'!$R$3:$R$60,"") | R24: =_xlfn.XLOOKUP(D24,'Rent Roll - RPM'!$B$3:$B$60,'Rent Roll - RPM'!$S$3:$S$60,"") | S24: 2650 | T24: =S24/L24 -> 1.6207951
A25: 1 | B25: 7 | C25: 105 | D25: =IF(ISNUMBER(SEARCH("Bobby Meadow",F25)),LEFT(F25,FIND(" ",F25)-1)&"M",LEFT(F25,FIND(" ",F25)-1)&MID(F25,FIND(" ",F25)+1,1)) -> 7311H | E25: =IFERROR(IF(_xlfn.XMATCH(D25,'Rent Roll - RPM'!$B$3:$B$60,0,1)>0,"Match","No Match"),"No Match") -> No Match | F25: 7311 Hadley Meadow Lane | G25: =_xlfn.XLOOKUP(D25,'Rent Roll - RPM'!$B$3:$B$60,'Rent Roll - RPM'!$D$3:$D$60,0) -> 0 | H25: 1 | I25: C2 | J25: Falcon | K25: 3 Bed | L25: 1909 | M25: 6 | N25: 46006 | O25: Turned | P25: =_xlfn.XLOOKUP(D25,'Rent Roll - RPM'!$B$3:$B$60,'Rent Roll - RPM'!$Q$3:$Q$60,"") | Q25: =_xlfn.XLOOKUP($D25,'Rent Roll - RPM'!$B$3:$B$60,'Rent Roll - RPM'!$R$3:$R$60,"") | R25: =_xlfn.XLOOKUP(D25,'Rent Roll - RPM'!$B$3:$B$60,'Rent Roll - RPM'!$S$3:$S$60,"") | S25: 3150 | T25: =S25/L25 -> 1.6500786
A26: 2 | B26: 3 | C26: 70 | D26: =IF(ISNUMBER(SEARCH("Bobby Meadow",F26)),LEFT(F26,FIND(" ",F26)-1)&"M",LEFT(F26,FIND(" ",F26)-1)&MID(F26,FIND(" ",F26)+1,1)) -> 7311L | E26: =IFERROR(IF(_xlfn.XMATCH(D26,'Rent Roll - RPM'!$B$3:$B$60,0,1)>0,"Match","No Match"),"No Match") -> No Match | F26: 7311 Leighton Meadow Lane | G26: =_xlfn.XLOOKUP(D26,'Rent Roll - RPM'!$B$3:$B$60,'Rent Roll - RPM'!$D$3:$D$60,0) -> 0 | H26: 1 | I26: E2 | J26: Sparrow | K26: 2 Bed | L26: 1635 | M26: 4 | N26: 45961 | O26: Turned | P26: =_xlfn.XLOOKUP(D26,'Rent Roll - RPM'!$B$3:$B$60,'Rent Roll - RPM'!$Q$3:$Q$60,"") | Q26: =_xlfn.XLOOKUP($D26,'Rent Roll - RPM'!$B$3:$B$60,'Rent Roll - RPM'!$R$3:$R$60,"") | R26: =_xlfn.XLOOKUP(D26,'Rent Roll - RPM'!$B$3:$B$60,'Rent Roll - RPM'!$S$3:$S$60,"") | S26: 2650 | T26: =S26/L26 -> 1.6207951
A27: 3 | B27: 14 | C27: 38 | D27: =IF(ISNUMBER(SEARCH("Bobby Meadow",F27)),LEFT(F27,FIND(" ",F27)-1)&"M",LEFT(F27,FIND(" ",F27)-1)&MID(F27,FIND(" ",F27)+1,1)) -> 7314C | E27: =IFERROR(IF(_xlfn.XMATCH(D27,'Rent Roll - RPM'!$B$3:$B$60,0,1)>0,"Match","No Match"),"No Match") -> No Match | F27: 7314 Corey Rushing Lane | G27: =_xlfn.XLOOKUP(D27,'Rent Roll - RPM'!$B$3:$B$60,'Rent Roll - RPM'!$D$3:$D$60,0) -> 0 | H27: 1 | I27: E3 | J27: Sparrow | K27: 2 Bed | L27: 1635 | M27: 2 | N27: Complete | O27: Turned | P27: =_xlfn.XLOOKUP(D27,'Rent Roll - RPM'!$B$3:$B$60,'Rent Roll - RPM'!$Q$3:$Q$60,"") | Q27: =_xlfn.XLOOKUP($D27,'Rent Roll - RPM'!$B$3:$B$60,'Rent Roll - RPM'!$R$3:$R$60,"") | R27: =_xlfn.XLOOKUP(D27,'Rent Roll - RPM'!$B$3:$B$60,'Rent Roll - RPM'!$S$3:$S$60,"") | S27: 2650 | T27: =S27/L27 -> 1.6207951
A28: 3 | B28: 18 | C28: 62 | D28: =IF(ISNUMBER(SEARCH("Bobby Meadow",F28)),LEFT(F28,FIND(" ",F28)-1)&"M",LEFT(F28,FIND(" ",F28)-1)&MID(F28,FIND(" ",F28)+1,1)) -> 7314L | E28: =IFERROR(IF(_xlfn.XMATCH(D28,'Rent Roll - RPM'!$B$3:$B$60,0,1)>0,"Match","No Match"),"No Match") -> No Match | F28: 7314 Leighton Meadow Lane | G28: =_xlfn.XLOOKUP(D28,'Rent Roll - RPM'!$B$3:$B$60,'Rent Roll - RPM'!$D$3:$D$60,0) -> 0 | H28: 1 | I28: E3 | J28: Sparrow | K28: 2 Bed | L28: 1635 | M28: 4 | N28: 45961 | O28: Turned | P28: =_xlfn.XLOOKUP(D28,'Rent Roll - RPM'!$B$3:$B$60,'Rent Roll - RPM'!$Q$3:$Q$60,"") | Q28: =_xlfn.XLOOKUP($D28,'Rent Roll - RPM'!$B$3:$B$60,'Rent Roll - RPM'!$R$3:$R$60,"") | R28: =_xlfn.XLOOKUP(D28,'Rent Roll - RPM'!$B$3:$B$60,'Rent Roll - RPM'!$S$3:$S$60,"") | S28: 2650 | T28: =S28/L28 -> 1.6207951
A29: 1 | B29: 8 | C29: 104 | D29: =IF(ISNUMBER(SEARCH("Bobby Meadow",F29)),LEFT(F29,FIND(" ",F29)-1)&"M",LEFT(F29,FIND(" ",F29)-1)&MID(F29,FIND(" ",F29)+1,1)) -> 7315H | E29: =IFERROR(IF(_xlfn.XMATCH(D29,'Rent Roll - RPM'!$B$3:$B$60,0,1)>0,"Match","No Match"),"No Match") -> No Match | F29: 7315 Hadley Meadow Lane | G29: =_xlfn.XLOOKUP(D29,'Rent Roll - RPM'!$B$3:$B$60,'Rent Roll - RPM'!$D$3:$D$60,0) -> 0 | H29: 1 | I29: F1 | J29: Raven | K29: 3 Bed | L29: 1852 | M29: 6 | N29: 46006 | O29: Turned | P29: =_xlfn.XLOOKUP(D29,'Rent Roll - RPM'!$B$3:$B$60,'Rent Roll - RPM'!$Q$3:$Q$60,"") | Q29: =_xlfn.XLOOKUP($D29,'Rent Roll - RPM'!$B$3:$B$60,'Rent Roll - RPM'!$R$3:$R$60,"") | R29: =_xlfn.XLOOKUP(D29,'Rent Roll - RPM'!$B$3:$B$60,'Rent Roll - RPM'!$S$3:$S$60,"") | S29: 2950 | T29: =S29/L29 -> 1.5928726
A30: 2 | B30: 4 | C30: 71 | D30: =IF(ISNUMBER(SEARCH("Bobby Meadow",F30)),LEFT(F30,FIND(" ",F30)-1)&"M",LEFT(F30,FIND(" ",F30)-1)&MID(F30,FIND(" ",F30)+1,1)) -> 7315L | E30: =IFERROR(IF(_xlfn.XMATCH(D30,'Rent Roll - RPM'!$B$3:$B$60,0,1)>0,"Match","No Match"),"No Match") -> No Match | F30: 7315 Leighton Meadow Lane | G30: =_xlfn.XLOOKUP(D30,'Rent Roll - RPM'!$B$3:$B$60,'Rent Roll - RPM'!$D$3:$D$60,0) -> 0 | H30: 1 | I30: E1 | J30: Sparrow | K30: 2 Bed | L30: 1635 | M30: 4 | N30: 45961 | O30: Turned | P30: =_xlfn.XLOOKUP(D30,'Rent Roll - RPM'!$B$3:$B$60,'Rent Roll - RPM'!$Q$3:$Q$60,"") | Q30: =_xlfn.XLOOKUP($D30,'Rent Roll - RPM'!$B$3:$B$60,'Rent Roll - RPM'!$R$3:$R$60,"") | R30: =_xlfn.XLOOKUP(D30,'Rent Roll - RPM'!$B$3:$B$60,'Rent Roll - RPM'!$S$3:$S$60,"") | S30: 2650 | T30: =S30/L30 -> 1.6207951
A31: 3 | B31: 13 | C31: 37 | D31: =IF(ISNUMBER(SEARCH("Bobby Meadow",F31)),LEFT(F31,FIND(" ",F31)-1)&"M",LEFT(F31,FIND(" ",F31)-1)&MID(F31,FIND(" ",F31)+1,1)) -> 7318C | E31: =IFERROR(IF(_xlfn.XMATCH(D31,'Rent Roll - RPM'!$B$3:$B$60,0,1)>0,"Match","No Match"),"No Match") -> No Match | F31: 7318 Corey Rushing Lane | G31: =_xlfn.XLOOKUP(D31,'Rent Roll - RPM'!$B$3:$B$60,'Rent Roll - RPM'!$D$3:$D$60,0) -> 0 | H31: 1 | I31: C1 | J31: Falcon | K31: 3 Bed | L31: 1909 | M31: 2 | N31: Complete | O31: Turned | P31: =_xlfn.XLOOKUP(D31,'Rent Roll - RPM'!$B$3:$B$60,'Rent Roll - RPM'!$Q$3:$Q$60,"") | Q31: =_xlfn.XLOOKUP($D31,'Rent Roll - RPM'!$B$3:$B$60,'Rent Roll - RPM'!$R$3:$R$60,"") | R31: =_xlfn.XLOOKUP(D31,'Rent Roll - RPM'!$B$3:$B$60,'Rent Roll - RPM'!$S$3:$S$60,"") | S31: 3150 | T31: =S31/L31 -> 1.6500786
A32: 2 | B32: 27 | C32: 117 | D32: =IF(ISNUMBER(SEARCH("Bobby Meadow",F32)),LEFT(F32,FIND(" ",F32)-1)&"M",LEFT(F32,FIND(" ",F32)-1)&MID(F32,FIND(" ",F32)+1,1)) -> 7318H | E32: =IFERROR(IF(_xlfn.XMATCH(D32,'Rent Roll - RPM'!$B$3:$B$60,0,1)>0,"Match","No Match"),"No Match") -> No Match | F32: 7318 Hadley Meadow Lane | G32: =_xlfn.XLOOKUP(D32,'Rent Roll - RPM'!$B$3:$B$60,'Rent Roll - RPM'!$D$3:$D$60,0) -> 0 | H32: 1 | I32: E1 | J32: Sparrow | K32: 2 Bed | L32: 1635 | M32: 6 | N32: 46006 | O32: Turned | P32: =_xlfn.XLOOKUP(D32,'Rent Roll - RPM'!$B$3:$B$60,'Rent Roll - RPM'!$Q$3:$Q$60,"") | Q32: =_xlfn.XLOOKUP($D32,'Rent Roll - RPM'!$B$3:$B$60,'Rent Roll - RPM'!$R$3:$R$60,"") | R32: =_xlfn.XLOOKUP(D32,'Rent Roll - RPM'!$B$3:$B$60,'Rent Roll - RPM'!$S$3:$S$60,"") | S32: 2650 | T32: =S32/L32 -> 1.6207951
A33: 3 | B33: 19 | C33: 63 | D33: =IF(ISNUMBER(SEARCH("Bobby Meadow",F33)),LEFT(F33,FIND(" ",F33)-1)&"M",LEFT(F33,FIND(" ",F33)-1)&MID(F33,FIND(" ",F33)+1,1)) -> 7318L | E33: =IFERROR(IF(_xlfn.XMATCH(D33,'Rent Roll - RPM'!$B$3:$B$60,0,1)>0,"Match","No Match"),"No Match") -> No Match | F33: 7318 Leighton Meadow Lane | G33: =_xlfn.XLOOKUP(D33,'Rent Roll - RPM'!$B$3:$B$60,'Rent Roll - RPM'!$D$3:$D$60,0) -> 0 | H33: 1 | I33: A1 | J33: Canary | K33: 2 Bed | L33: 1425 | M33: 4 | N33: 45961 | O33: Turned | P33: =_xlfn.XLOOKUP(D33,'Rent Roll - RPM'!$B$3:$B$60,'Rent Roll - RPM'!$Q$3:$Q$60,"") | Q33: =_xlfn.XLOOKUP($D33,'Rent Roll - RPM'!$B$3:$B$60,'Rent Roll - RPM'!$R$3:$R$60,"") | R33: =_xlfn.XLOOKUP(D33,'Rent Roll - RPM'!$B$3:$B$60,'Rent Roll - RPM'!$S$3:$S$60,"") | S33: 2450 | T33: =S33/L33 -> 1.7192982
A34: 1 | B34: 9 | C34: 103 | D34: =IF(ISNUMBER(SEARCH("Bobby Meadow",F34)),LEFT(F34,FIND(" ",F34)-1)&"M",LEFT(F34,FIND(" ",F34)-1)&MID(F34,FIND(" ",F34)+1,1)) -> 7319H | E34: =IFERROR(IF(_xlfn.XMATCH(D34,'Rent Roll - RPM'!$B$3:$B$60,0,1)>0,"Match","No Match"),"No Match") -> No Match | F34: 7319 Hadley Meadow Lane | G34: =_xlfn.XLOOKUP(D34,'Rent Roll - RPM'!$B$3:$B$60,'Rent Roll - RPM'!$D$3:$D$60,0) -> 0 | H34: 1 | I34: F3 | J34: Raven | K34: 3 Bed | L34: 1852 | M34: 6 | N34: 46006 | O34: Turned | P34: =_xlfn.XLOOKUP(D34,'Rent Roll - RPM'!$B$3:$B$60,'Rent Roll - RPM'!$Q$3:$Q$60,"") | Q34: =_xlfn.XLOOKUP($D34,'Rent Roll - RPM'!$B$3:$B$60,'Rent Roll - RPM'!$R$3:$R$60,"") | R34: =_xlfn.XLOOKUP(D34,'Rent Roll - RPM'!$B$3:$B$60,'Rent Roll - RPM'!$S$3:$S$60,"") | S34: 2950 | T34: =S34/L34 -> 1.5928726
A35: 2 | B35: 5 | C35: 72 | D35: =IF(ISNUMBER(SEARCH("Bobby Meadow",F35)),LEFT(F35,FIND(" ",F35)-1)&"M",LEFT(F35,FIND(" ",F35)-1)&MID(F35,FIND(" ",F35)+1,1)) -> 7319L | E35: =IFERROR(IF(_xlfn.XMATCH(D35,'Rent Roll - RPM'!$B$3:$B$60,0,1)>0,"Match","No Match"),"No Match") -> No Match | F35: 7319 Leighton Meadow Lane | G35: =_xlfn.XLOOKUP(D35,'Rent Roll - RPM'!$B$3:$B$60,'Rent Roll - RPM'!$D$3:$D$60,0) -> 0 | H35: 1 | I35: A2 | J35: Canary | K35: 2 Bed | L35: 1425 | M35: 4 | N35: 45961 | O35: Turned | P35: =_xlfn.XLOOKUP(D35,'Rent Roll - RPM'!$B$3:$B$60,'Rent Roll - RPM'!$Q$3:$Q$60,"") | Q35: =_xlfn.XLOOKUP($D35,'Rent Roll - RPM'!$B$3:$B$60,'Rent Roll - RPM'!$R$3:$R$60,"") | R35: =_xlfn.XLOOKUP(D35,'Rent Roll - RPM'!$B$3:$B$60,'Rent Roll - RPM'!$S$3:$S$60,"") | S35: 2450 | T35: =S35/L35 -> 1.7192982
A36: 2 | B36: 26 | C36: 116 | D36: =IF(ISNUMBER(SEARCH("Bobby Meadow",F36)),LEFT(F36,FIND(" ",F36)-1)&"M",LEFT(F36,FIND(" ",F36)-1)&MID(F36,FIND(" ",F36)+1,1)) -> 7322H | E36: =IFERROR(IF(_xlfn.XMATCH(D36,'Rent Roll - RPM'!$B$3:$B$60,0,1)>0,"Match","No Match"),"No Match") -> No Match | F36: 7322 Hadley Meadow Lane | G36: =_xlfn.XLOOKUP(D36,'Rent Roll - RPM'!$B$3:$B$60,'Rent Roll - RPM'!$D$3:$D$60,0) -> 0 | H36: 1 | I36: A3 | J36: Canary | K36: 2 Bed | L36: 1425 | M36: 6 | N36: 46006 | O36: Turned | P36: =_xlfn.XLOOKUP(D36,'Rent Roll - RPM'!$B$3:$B$60,'Rent Roll - RPM'!$Q$3:$Q$60,"") | Q36: =_xlfn.XLOOKUP($D36,'Rent Roll - RPM'!$B$3:$B$60,'Rent Roll - RPM'!$R$3:$R$60,"") | R36: =_xlfn.XLOOKUP(D36,'Rent Roll - RPM'!$B$3:$B$60,'Rent Roll - RPM'!$S$3:$S$60,"") | S36: 2450 | T36: =S36/L36 -> 1.7192982
A37: 3 | B37: 20 | C37: 64 | D37: =IF(ISNUMBER(SEARCH("Bobby Meadow",F37)),LEFT(F37,FIND(" ",F37)-1)&"M",LEFT(F37,FIND(" ",F37)-1)&MID(F37,FIND(" ",F37)+1,1)) -> 7322L | E37: =IFERROR(IF(_xlfn.XMATCH(D37,'Rent Roll - RPM'!$B$3:$B$60,0,1)>0,"Match","No Match"),"No Match") -> No Match | F37: 7322 Leighton Meadow Lane | G37: =_xlfn.XLOOKUP(D37,'Rent Roll - RPM'!$B$3:$B$60,'Rent Roll - RPM'!$D$3:$D$60,0) -> 0 | H37: 1 | I37: B2 | J37: Mallard | K37: 3 Bed | L37: 1685 | M37: 4 | N37: 45961 | O37: Turned | P37: =_xlfn.XLOOKUP(D37,'Rent Roll - RPM'!$B$3:$B$60,'Rent Roll - RPM'!$Q$3:$Q$60,"") | Q37: =_xlfn.XLOOKUP($D37,'Rent Roll - RPM'!$B$3:$B$60,'Rent Roll - RPM'!$R$3:$R$60,"") | R37: =_xlfn.XLOOKUP(D37,'Rent Roll - RPM'!$B$3:$B$60,'Rent Roll - RPM'!$S$3:$S$60,"") | S37: 2750 | T37: =S37/L37 -> 1.6320475
A38: 2 | B38: 6 | C38: 73 | D38: =IF(ISNUMBER(SEARCH("Bobby Meadow",F38)),LEFT(F38,FIND(" ",F38)-1)&"M",LEFT(F38,FIND(" ",F38)-1)&MID(F38,FIND(" ",F38)+1,1)) -> 7323L | E38: =IFERROR(IF(_xlfn.XMATCH(D38,'Rent Roll - RPM'!$B$3:$B$60,0,1)>0,"Match","No Match"),"No Match") -> No Match | F38: 7323 Leighton Meadow Lane | G38: =_xlfn.XLOOKUP(D38,'Rent Roll - RPM'!$B$3:$B$60,'Rent Roll - RPM'!$D$3:$D$60,0) -> 0 | H38: 1 | I38: E2 | J38: Sparrow | K38: 2 Bed | L38: 1635 | M38: 4 | N38: 45961 | O38: Turned | P38: =_xlfn.XLOOKUP(D38,'Rent Roll - RPM'!$B$3:$B$60,'Rent Roll - RPM'!$Q$3:$Q$60,"") | Q38: =_xlfn.XLOOKUP($D38,'Rent Roll - RPM'!$B$3:$B$60,'Rent Roll - RPM'!$R$3:$R$60,"") | R38: =_xlfn.XLOOKUP(D38,'Rent Roll - RPM'!$B$3:$B$60,'Rent Roll - RPM'!$S$3:$S$60,"") | S38: 2650 | T38: =S38/L38 -> 1.6207951
A39: 2 | B39: 25 | C39: 115 | D39: =IF(ISNUMBER(SEARCH("Bobby Meadow",F39)),LEFT(F39,FIND(" ",F39)-1)&"M",LEFT(F39,FIND(" ",F39)-1)&MID(F39,FIND(" ",F39)+1,1)) -> 7326H | E39: =IFERROR(IF(_xlfn.XMATCH(D39,'Rent Roll - RPM'!$B$3:$B$60,0,1)>0,"Match","No Match"),"No Match") -> No Match | F39: 7326 Hadley Meadow Lane | G39: =_xlfn.XLOOKUP(D39,'Rent Roll - RPM'!$B$3:$B$60,'Rent Roll - RPM'!$D$3:$D$60,0) -> 0 | H39: 1 | I39: A1 | J39: Canary | K39: 2 Bed | L39: 1425 | M39: 6 | N39: 46006 | O39: Turned | P39: =_xlfn.XLOOKUP(D39,'Rent Roll - RPM'!$B$3:$B$60,'Rent Roll - RPM'!$Q$3:$Q$60,"") | Q39: =_xlfn.XLOOKUP($D39,'Rent Roll - RPM'!$B$3:$B$60,'Rent Roll - RPM'!$R$3:$R$60,"") | R39: =_xlfn.XLOOKUP(D39,'Rent Roll - RPM'!$B$3:$B$60,'Rent Roll - RPM'!$S$3:$S$60,"") | S39: 2450 | T39: =S39/L39 -> 1.7192982
A40: 1 | B40: 11 | C40: 101 | D40: =IF(ISNUMBER(SEARCH("Bobby Meadow",F40)),LEFT(F40,FIND(" ",F40)-1)&"M",LEFT(F40,FIND(" ",F40)-1)&MID(F40,FIND(" ",F40)+1,1)) -> 7327H | E40: =IFERROR(IF(_xlfn.XMATCH(D40,'Rent Roll - RPM'!$B$3:$B$60,0,1)>0,"Match","No Match"),"No Match") -> No Match | F40: 7327 Hadley Meadow Lane | G40: =_xlfn.XLOOKUP(D40,'Rent Roll - RPM'!$B$3:$B$60,'Rent Roll - RPM'!$D$3:$D$60,0) -> 0 | H40: 1 | I40: F2 | J40: Raven | K40: 3 Bed | L40: 1852 | M40: 6 | N40: 46006 | O40: Turned | P40: =_xlfn.XLOOKUP(D40,'Rent Roll - RPM'!$B$3:$B$60,'Rent Roll - RPM'!$Q$3:$Q$60,"") | Q40: =_xlfn.XLOOKUP($D40,'Rent Roll - RPM'!$B$3:$B$60,'Rent Roll - RPM'!$R$3:$R$60,"") | R40: =_xlfn.XLOOKUP(D40,'Rent Roll - RPM'!$B$3:$B$60,'Rent Roll - RPM'!$S$3:$S$60,"") | S40: 2950 | T40: =S40/L40 -> 1.5928726
...

Sheet Rent Roll - RPM
B1: Unit | C1: Resident | D1: Name | E1: Resident | F1: Unit | G1: Resident | H1: Unit | I1: Status | J1: Days | K1: Make | L1: Move | M1: Hold | N1: Hold | O1: Notice | P1: Move | Q1: Lease | R1: Lease | S1: Lease
E2: Rent | F2: Rent | G2: Deposit | H2: Deposit | J2: Vacant | K2: Ready | L2: In | N2: Until | P2: Out | Q2: Sign | R2: From | S2: To
B3: 22026F | C3: t0908304 | D3: Maxwell, Felicia | E3: 2650 | F3: 2650 | G3: 1000 | H3: 0 | I3: Notice | K3: 45772 | L3: 45778 | M3: No | O3: 46099 | P3: 46173 | Q3: 45776 | R3: 45778 | S3: 46173 | T3: Paste here leased not moved in
B4: 7306C | C4: t0913318 | D4: Williams, Anthony | E4: 2750 | F4: 2750 | G4: 0 | H4: 0 | I4: Applicant | J4: 475 | K4: 45891 | L4: 46150 | M4: No | R4: 46113 | S4: 46568
B5: 22029L | C5: t0751889 | D5: Maxwell, Felicia | E5: 3600 | F5: 3600 | G5: 0 | H5: 0 | I5: Future | J5: 219 | K5: 45891 | L5: 46174 | M5: No | Q5: 46099 | R5: 46174 | S5: 46568
B6: 7431L | C6: t0902211 | D6: Jones, Jillian | E6: 2650 | F6: 2650 | G6: 0 | H6: 0 | I6: Future | J6: 440 | K6: 45987 | L6: 46127 | M6: No | R6: 46127 | S6: 46521
B7: 22013L | C7: t0903492 | D7: Ajah, Grace | E7: 2950 | F7: 2950 | G7: 0 | H7: 0 | I7: Future | J7: 475 | K7: 45891 | L7: 46111 | M7: No | R7: 46111 | S7: 46506
T9: Paste here moved in units
B10: 21914F | C10: t0836706 | D10: Smith, Audrey | E10: 2450 | F10: 2450 | G10: 2450 | H10: 0 | I10: Current | K10: 46047 | L10: 46066 | M10: No | Q10: 45943 | R10: 46066 | S10: 46458
B11: 21915M | C11: t0840997 | D11: Hockaday, Gordon | E11: 2450 | F11: 2450 | G11: 2450 | H11: 0 | I11: Current | K11: 45993 | L11: 45993 | M11: No | Q11: 45950 | R11: 45993 | S11: 46447
B12: 21938M | C12: t0748186 | D12: Posadas, Yolanda | E12: 2450 | F12: 2450 | G12: 2450 | H12: 0 | I12: Current | K12: 45863 | L12: 45865 | M12: No | Q12: 45778 | R12: 45865 | S12: 46321
B13: 21946M | C13: t0810731 | D13: Odom, Clayton | E13: 2450 | F13: 2450 | G13: 2450 | H13: 0 | I13: Current | K13: 45911 | L13: 45916 | M13: No | Q13: 45916 | R13: 45916 | S13: 46371
B14: 21950M | C14: t0845369 | D14: Thomas, C Yvette | E14: 2450 | F14: 2450 | G14: 500 | H14: 0 | I14: Current | K14: 45923 | L14: 45999 | M14: No | Q14: 45961 | R14: 45999 | S14: 46394
B15: 22002F | C15: t0773895 | D15: Agbo, Chinwe | E15: 2450 | F15: 2450 | G15: 500 | H15: 0 | I15: Current | K15: 45754 | L15: 45829 | M15: No | Q15: 45821 | R15: 45829 | S15: 46223
B16: 22011F | C16: t0737373 | D16: Smith, Gabrielle | E16: 2450 | F16: 2450 | G16: 1000 | H16: 0 | I16: Current | K16: 45754 | L16: 45878 | M16: No | Q16: 45744 | R16: 45878 | S16: 46334
B17: 22014F | C17: t0743361 | D17: Green, Dominique | E17: 2450 | F17: 2450 | G17: 2450 | H17: 0 | I17: Current | K17: 45754 | L17: 45782 | M17: No | Q17: 45757 | R17: 45782 | S17: 46177
B18: 22015F | C18: t0742291 | D18: Olmsted, Deborah | E18: 2450 | F18: 2450 | G18: 1000 | H18: 0 | I18: Current | K18: 45754 | L18: 45777 | M18: No | Q18: 45758 | R18: 45777 | S18: 46232
B19: 22030F | C19: t0759978 | D19: Roberts, Melissa | E19: 2450 | F19: 2450 | G19: 2450 | H19: 0 | I19: Current | K19: 45772 | L19: 45800 | M19: No | Q19: 45797 | R19: 45800 | S19: 46195
B20: 22033L | C20: t0788773 | D20: Ciftci, Irmak | E20: 2450 | F20: 2450 | G20: 500 | H20: 0 | I20: Current | K20: 45859 | L20: 45870 | M20: No | Q20: 45856 | R20: 45870 | S20: 46265
B21: 22034F | C21: t0781667 | D21: Maynard, Joseph | E21: 2450 | F21: 2450 | G21: 500 | H21: 0 | I21: Current | K21: 45804 | L21: 45836 | M21: No | Q21: 45834 | R21: 45836 | S21: 46230
... B60: 7411H | C60: t0890574 | D60: Contreras, Kristina | E60: 2950 | F60: 2950 | G60: 500 | H60: 0 | I60: Current | K60: 46014 | L60: 46073 | M60: No | Q60: 46064 | R60: 46073 | S60: 46526

Sheet Lease Tracker
A1: LIGHTHAVEN | I1: A | J1: Canary
A2: LEASING STATUS | I2: B | J2: Mallard
B4: LEASED - NOT MOVED IN | C4: RESIDENT NAME | D4: MOVE IN DATE: | E4: PLAN TYPE
A5: 1
A6: =A5+1 -> 2 | B6: 7303 Leighton Meadow | C6: Phoebo Akloyo | D6: 45776 | E6: Raven | H6: Actual | I6: 45955 | J6: 45986 | K6: 46016 | L6: 46023 | M6: 46054 | N6: 46082 | O6: 46113 | P6: 46143 | Q6: 46174 | R6: 46204 | S6: 46235 | T6: 46266 | U6: 46296 | V6: 46327 | W6: 46357
A7: =A6+1 -> 3 | B7: 22029 Lesley Grove Lane | C7: Felicia Maxwell (onsite Transfer) | D7: 46174 | E7: Phoenix | H7: Beg Occ | I7: 21 | J7: =I8 -> 23 | K7: =J8 -> 27 | L7: =K8 -> 33 | M7: =L8 -> 41 | N7: =M8 -> 47 | O7: =N8 -> 53 | P7: =O8 -> 56 | Q7: =P8 -> 57 | ... W7: =V8 -> 57
A8: =A7+1 -> 4 | H8: Ending Occ | I8: 23 | J8: 27 | K8: 33 | L8: =K8+8 -> 41 | M8: =L8+M15+M14 -> 47 | N8: =M8+N15+N14 -> 53 | O8: =N8+O15+O14 -> 56 | P8: =O8+P15+P14 -> 57 | Q8: =P8+Q15+Q14 -> 57 | R8: =Q8+R15+R14 -> 57 | S8: =R8+S15+S14 -> 57 | T8: =S8+T15+T14 -> 57 | ... W8: =V8+W15+W14 -> 57
A9: =A8+1 -> 5 | H9: OCC % | I9: =I8/117 -> 0.1965812 | J9: =J8/117 -> 0.23076923 | K9: =K8/117 -> 0.28205128 | L9: =L8/117 -> 0.35042735 | M9: =M8/117 -> 0.4017094 | N9: =N8/117 -> 0.45299145 | O9: =O8/117 -> 0.47863248 | P9: =P8/117 -> 0.48717949 | ... W9: =W8/117 -> 0.48717949
A10: =A9+1 -> 6
A11: =A10+1 -> 7 | H11: Cumulative Leased | I11: =J11-J13 -> 29 | J11: 33 | K11: 39 | L11: 47 | M11: =L11+M13 -> 52 | N11: =M11+N13 -> 55 | O11: =N11+O13 -> 58 | P11: =O11+P13 -> 58 | Q11: =P11+Q13 -> 58 | R11: =Q11+R13 -> 58 | S11: =R11+S13 -> 58 | T11: =S11+T13 -> 58 | ... W11: =V11+W13 -> 58
A12: =A11+1 -> 8 | F12: % OCC | H12: % Leased | I12: =I11/117 -> 0.24786325 | J12: =J11/117 -> 0.28205128 | K12: =K11/117 -> 0.33333333 | L12: =L11/117 -> 0.4017094 | M12: =M11/117 -> 0.44444444 | N12: =N11/117 -> 0.47008547 | O12: =O11/117 -> 0.4957265 | P12: =P11/117 -> 0.4957265 | ... W12: =W11/117 -> 0.4957265
A13: =A12+1 -> 9 | H13: # of leases signed | I13: 8 | J13: 4 | K13: =K11-J11 -> 6 | L13: =L11-K11 -> 8 | M13: 5 | N13: 3 | O13: 3
A14: =A13+1 -> 10 | H14: # of Move-ins | I14: 1 | J14: =J8-J7 -> 4 | K14: =K8-K7 -> 6 | L14: =L8-L7 -> 8 | M14: 7 | N14: 6 | O14: 3 | P14: 1 | Q14: 1
H15: # of Move-outs / transfers | I15: 0 | J15: 0 | K15: 0 | L15: 0 | M15: -1 | Q15: -1
B16: LEASED - MOVED IN | D16: MOVE IN DATE: | E16: PLAN TYPE
A17: 1 | B17: 22015 Ferguson Meadow Lane | D17: 45777 | E17: A.2 | H17: 2026 Budget
A18: =A17+1 -> 2 | B18: 22026 Ferguson Meadow Lane | C18: Felicia Maxwell (onsite Transfer) | D18: 45778 | E18: E.1 | F18: Onsite Transfer 05/31/26 | H18: Beginning Occ | L18: 33 | M18: 40 | N18: 47 | O18: 52 | P18: 58 | Q18: 68 | R18: 77 | S18: 85 | T18: 91 | U18: 96 | V18: 100 | W18: 104
A19: =A18+1 -> 3 | B19: 22037 Lesley Grove Lane | D19: 45778 | E19: E.2 | H19: Ending Occ | L19: =L18+L20 -> 38 | M19: =M18+M20 -> 45 | N19: =N18+N20 -> 52 | O19: =O18+O20 -> 58 | P19: =P18+P20 -> 68 | Q19: =Q18+Q20 -> 77 | R19: =R18+R20 -> 85 | S19: =S18+S20 -> 91 | ... W19: =W18+W20 -> 107
A20: =A19+1 -> 4 | B20: 22014 Ferguson Meadow Lane | D20: 45782 | E20: B.1 | H20: # of Leases / month | L20: 5 | M20: 5 | N20: 5 | O20: 6 | P20: 10 | Q20: 9 | R20: 8 | S20: 6 | T20: 5 | U20: 4 | V20: 4 | W20: 3
A21: =A20+1 -> 5 | B21: 22030 Ferguson Meadow Lane | D21: 45800 | E21: A
A22: =A21+1 -> 6 | B22: 22018 Ferguson Meadow Lane | D22: 45809 | E22: B | H22: Projected Occ, Actual to Budget | M22: =(M11/117)*100 -> 44.444444
A23: =A22+1 -> 7 | B23: 22045 Lesley Grove Lane | D23: 45819 | E23: A
A24: =A23+1 -> 8 | B24: 22002 Ferguson Meadow Lane | D24: 45829 | E24: A | H24: Gross Absorption = Total number of units leased | N24: =K11-L11 -> -8
A25: =A24+1 -> 9 | B25: 22034 Ferguson Meadow Lane | D25: 45835 | E25: A | H25: Net Absorption = Total number of units leased minus the number of units vacated.
A26: =A25+1 -> 10 | B26: 22026 Lesley Grove Lane | D26: 45836 | E26: D
A27: =A26+1 -> 11 | B27: 22027 Ferguson Meadow Lane | D27: 45839 | E27: B
A28: =A27+1 -> 12 | B28: 21917 Bruce Rushing Lane | C28: L. Jeffrey | D28: 7/18/205 | E28: B.1
A29: =A28+1 -> 13 | B29: 22038 Ferguson Meadow Lane | D29: 45856 | E29: A
A30: =A29+1 -> 14 | B30: 21938 Bobby Meadow Lane | C30: Y Posadas | D30: 45865 | E30: A.2 | O30: =18/3 -> 6
A31: =A30+1 -> 15 | B31: 22023 Ferguson Meadow Lane | D31: 45863 | E31: F
A32: =A31+1 -> 16 | B32: 22041 Lesley Grove | D32: 46228 | E32: F
A33: =A32+1 -> 17 | B33: 22033 Lesley Grove | D33: 45870 | E33: A
A34: =A33+1 -> 18 | B34: 22005 Lesley Grove | D34: 45874 | E34: C
A35: =A34+1 -> 19 | B35: 21909 Bruce Rushing Lane | C35: H. Kim | D35: 45875 | E35: A | F35: Early Term - Relocating out of state - paying early term fee on 1/1 with rent. Move-out 2/14
A36: =A34+1 -> 19 | B36: 22011 Ferguson Meadow | D36: 45878 | E36: A.1
A37: =A36+1 -> 20 | B37: 21946 Bruce Rushing Lane | C37: C Odom | D37: 45898 | E37: A
A38: =A37+1 -> 21 | B38: 21939 Bobby Meadow Lane | C38: S Cheeks | D38: 45941 | E38: B
A39: =A38+1 -> 22 | B39: 7302 Corey Rushing Lane | D39: 45975 | E39: B
A40: =A39+1 -> 23 | B40: 22025 Lesley Grove Lane | D40: 45962 | E40: C1
A41: =A40+1 -> 24 | B41: 21954 Bobby meadow | D41: 45965 | E41: B
...

Sheet Weekly Traffic
A1: 2026 Traffic Tracking Sheet
A2: January 2026
C3: Prospect | D3: Tours | E3: Apps | F3: Leases | G3: Cancels | H3: Denials | J3: Website | K3: Google Paid Search | L3: Zillow | M3: RentCafe | N3: Drive By | O3: Apt list | P3: Locaters | Q3: Direct mailer | R3: Google Biz | S3: Banners/Signage | T3: Knock | U3: Total
A4: Week 1 | B4: 12/29 -1/4 | C4: 28 | D4: 14 | E4: 5 | F4: =E4-G4-H4 -> 4 | G4: 1 | H4: 0 | J4: 11 | K4: 3 | L4: 2 | M4: 2 | N4: 6 | O4: 1 | P4: 2 | Q4: 1 | U4: =SUM(J4:R4) -> 28
A5: Week 2 | B5: 1/5 - 1/11 | C5: 22 | D5: 10 | E5: 3 | F5: =E5-G5-H5 -> 1 | G5: 0 | H5: 2 | J5: 6 | K5: 1 | L5: 2 | N5: 4 | P5: 4 | R5: 3 | S5: 1 | T5: 1 | U5: =SUM(J5:T5) -> 22
A6: Week 3 | B6: 1/12-1/18 | C6: 23 | D6: 8 | E6: 3 | F6: =E6-G6-H6 -> 2 | G6: 1 | H6: 0 | J6: 8 | K6: 4 | L6: 0 | M6: 2 | N6: 3 | O6: 0 | P6: 2 | Q6: 0 | R6: 3 | S6: 0 | T6: 1 | U6: =SUM(J6:T6) -> 23
A7: Week 4 | B7: 1/19-1/25 | C7: 25 | D7: 7 | E7: 2 | F7: =E7-G7-H7 -> 1 | G7: 0 | H7: 1 | U7: =SUM(J7:R7) -> 0
A8: Week 5 | B8: 1/26-2/1 | C8: 24 | D8: 8 | E8: 2 | F8: 0 | G8: 0 | H8: 1
A9: TOTALS - January | C9: =SUM(C4:C8) -> 122 | D9: =SUM(D4:D8) -> 47 | E9: =SUM(E4:E8) -> 15 | F9: =SUM(F4:F8) -> 8 | G9: =SUM(G4:G8) -> 2 | H9: =SUM(H4:H8) -> 4 | J9: =SUM(J4:J7) -> 25 | K9: =SUM(K4:K7) -> 8 | L9: =SUM(L4:L7) -> 4 | M9: =SUM(M4:M7) -> 4 | N9: =SUM(N4:N7) -> 13 | O9: =SUM(O4:O7) -> 1 | P9: =SUM(P4:P7) -> 8 | Q9: =SUM(Q4:Q7) -> 1 | ... U9: =SUM(U4:U7) -> 73
A10: conversions | D10: =D9/C9 -> 0.3852459 | E10: =E9/D9 -> 0.31914894 | F10: =F9/E9 -> 0.53333333 | J10: =J9/$U$28 -> 0.34246575 | K10: =K9/$U$28 -> 0.10958904 | L10: =L9/$U$28 -> 0.054794521 | M10: =M9/$U$28 -> 0.054794521 | N10: =N9/$U$28 -> 0.17808219 | O10: =O9/$U$28 -> 0.01369863 | P10: =P9/$U$28 -> 0.10958904 | Q10: =Q9/$U$28 -> 0.01369863 | ... U10: =U9/$U$28 -> 1
A11: 46054
C12: Prospect | D12: Tours | E12: Apps | F12: Leases | G12: Cancels | H12: Denials
A13: Week 6 | B13: 2/2-2/8 | C13: 17 | D13: 9 | E13: 2 | F13: 2 | G13: 0 | H13: 0 | U13: =SUM(J13:R13) -> 0
A14: Week 7 | B14: 2/9-2/15 | C14: 16 | D14: 3 | E14: 1 | F14: =E14-G14-H14 -> 1 | G14: 0 | H14: 0 | K14: 5 | M14: 4 | N14: 2 | S14: 2 | U14: =SUM(J14:R14) -> 11
A15: Week 8 | B15: 2/16-2/22 | C15: 19 | D15: 3 | E15: 2 | F15: =E15-G15-H15 -> 1 | G15: 1 | H15: 0 | J15: 3 | K15: 5 | L15: 1 | N15: 3 | P15: 4 | R15: 1 | S15: 1
A16: Week 9 | B16: 2/23-03/01 | C16: 13 | D16: 3 | E16: 2 | F16: =E16-G16-H16 -> 1 | G16: 0 | H16: 1 | J16: 6 | K16: 4 | L16: 1 | N16: 1
A17: TOTALS - February | C17: =SUM(C13:C16) -> 65 | D17: =SUM(D13:D16) -> 18 | E17: =SUM(E13:E16) -> 7 | F17: =SUM(F13:F16) -> 5 | G17: =SUM(G13:G16) -> 1 | H17: =SUM(H13:H16) -> 1 | J17: =SUM(J13:J16) -> 9 | K17: =SUM(K13:K16) -> 14 | L17: =SUM(L13:L16) -> 2 | M17: =SUM(M13:M16) -> 4 | N17: =SUM(N13:N16) -> 6 | O17: =SUM(O13:O16) -> 0 | P17: =SUM(P13:P16) -> 4 | Q17: =SUM(Q13:Q16) -> 0 | ... U17: =SUM(U13:U16) -> 11
A19: Week 10 | B19: 3/2-3/8 | C19: 6 | F19: =E19-G19-H19 -> 0
